Workbook
Name _Abrechnungstarif_LEG: Eingaben!$C$61
Name _Abzug_Funktion_GH: Eingaben!$C$90
Name _Abzug_Funktion_Notstrom: Eingaben!$C$102
Name _Amortisationszeit: Berechnungen!$BR$53
Name _Amortisationszeit_Batterie: Berechnungen!$CD$53
Name _Amortisationszeit_PVA_Batterie: Berechnungen!$BX$53
Name _Anlagekategorie: Eingaben!$B$16
Name _Anlagenlebensdauer: Eingaben!$C$20
Name _Anlagenleistung: Eingaben!$C$17
Name _Anteil_LEG: Eingaben!$C$58
Name _Anzahl_Verbraucher: Eingaben!$C$42
Name _Batterie: Eingaben!$C$26
Name _Bemerkungen: Eingaben!$B$11
Name _Berechnungsart_Unterhaltskosten: Eingaben!$B$111
Name _Betreiber: Eingaben!$B$4
Name _Dach_angebaut: Listen!$C$5
Name _Dach_integriert: Listen!$C$4
Name _Debug_Modus: Eingaben!$O$2
Name _Degradation: Eingaben!$C$23
Name _Degradation_Speicher_Jahr: Eingaben!$C$31
Name _direkteFörderung: Eingaben!$C$81
Name _durchschnittlich_Energie_eingelagert: Berechnungen!$O$54
Name _Durchschnittliche_Betriebskosten_LEG: Berechnungen!$AZ$54
Name _Durchschnittliche_Betriebskosten_ZEV: Berechnungen!$AY$54
Name _Durchschnittliche_Eigenkapitalkosten: Berechnungen!$BH$54
Name _Durchschnittliche_Eigenkapitalkosten_Batterie: Berechnungen!$BK$54
Name _durchschnittliche_Einsparung_Leistung: Berechnungen!$Y$54
Name _durchschnittliche_Einsparung_Leistung_Batterie: Berechnungen!$AD$54
Name _Durchschnittliche_Kost_Ersatz_Batterie: Berechnungen!$BA$54
Name _durchschnittliche_Kosten_Energie_Speicher: Berechnungen!$AE$54
Name _Durchschnittliche_Umsatzsteuer: Berechnungen!$BB$54
Name _Durchschnittliche_Unterhaltskosten: Berechnungen!$AX$54
Name _Durchschnittliche_Unterhaltskosten_Batterie: Berechnungen!$BA$54
Name _Durchschnittliche_Vergütung_Rücklieferung: Berechnungen!$S$54
Name _Durchschnittliche_Vorsteuer_Batterieersatz: Berechnungen!$BD$54
Name _Durchschnittliche_Vorsteuer_Unterhalt: Berechnungen!$BC$54
Name _Durchschnittlicher_Abrechnungsgebühren_ZEV: Berechnungen!$AB$54
Name _Durchschnittlicher_Energieertrag: Berechnungen!$K$54
Name _Durchschnittlicher_Speichermenge: Berechnungen!$Q$54
Name _Durchschnittlicher_Verkauf_Batteriestrom: Berechnungen!$AC$54
Name _durchschnittlicher_Verkauf_LEG: Berechnungen!$U$54
Name _Durchschnittlicher_Verkauf_Solarstrom: Berechnungen!$W$54
Name _Durchschnittlicher_Zins_FK_Batterie: Berechnungen!$BL$54
Name _Durchschnittlicher_Zins_FK1: Berechnungen!$BI$54
Name _Durchschnittlicher_Zins_FK2: Berechnungen!$BJ$54
Name _Eigenkapital: Eingaben!$C$95
Name _Eigenkapital_Batterie: Eingaben!$C$107
Name _Eigenkapitalrendite: Bericht!$B$18
Name _Eigennutzungsgrad: Eingaben!$C$45
Name _Eigennutzungsgrad_Batterie: Eingaben!$C$32
Name _Einmalvergütung: Eingaben!$C$76
Name _Erhöhung_Eigennutzungsgrad_Speicher: Eingaben!$C$33
Name _ersetzterBezugstarifZEV: Eingaben!$C$47
Name _f_Ersatztarif: Eingaben!#REF!
Name _Fassade_angebaut: Listen!$C$7
Name _Fassade_integriert: Listen!$C$6
Name _Fassadenbonus: Eingaben!$C$77
Name _Förderung_Batterie: Eingaben!$C$83
Name _freistehend: Listen!$C$9
Name _Fremdkapital_Batterie: Eingaben!$C$108

Sheet Bericht
A1: Projektangaben | K1: =_xlfn.TRANSLATE(A1,"de", "en") -> Project information
A2: Projektbezeichnung: | B2: =_Projektbezeichnung&", "&_Standort -> , | K2: =_xlfn.TRANSLATE(A2,"de", "en") -> Project name:
K3: =_xlfn.TRANSLATE(A3,"de", "en")
A4: Projektnummer: | B4: =IF(_Projektnummer<>"",_Projektnummer,"") | F4: Projektleiter: | G4: =IF(_Projektleiter<>"",_Projektleiter,"") | K4: =_xlfn.TRANSLATE(A4,"de", "en") -> Project number:
A5: Betreiber / Investor: | B5: =IF(_Betreiber<>"",_Betreiber,"") | F5: MWSt. Pflicht | G5: =_MWStPflicht -> MWSt. pflichtig | K5: =_xlfn.TRANSLATE(A5,"de", "en") -> Operator / Investor:
K6: =_xlfn.TRANSLATE(A6,"de", "en")
A7: Bemerkungen: | B7: =IF(_Bemerkungen<>"",_Bemerkungen,"") | K7: =_xlfn.TRANSLATE(A7,"de", "en") -> Remarks:
A8: Netzbetreiber: | B8: =IF(Eingaben!B10<>"",Eingaben!B10,"") | K8: =_xlfn.TRANSLATE(A8,"de", "en") -> Common carrier:
K9: =_xlfn.TRANSLATE(A9,"de", "en")
A10: Wirtschaftlichkeitsberechnung | I10: ="Version Swissolar: " & _Version -> Version Swissolar: V2.4 | K10: =_xlfn.TRANSLATE(A10,"de", "en") -> Profitability calculation
K11: =_xlfn.TRANSLATE(A11,"de", "en")
A12: Kennzahlen PV- Anlage | F12: Kennzahlen PV- Anlage und Batteriespeicher | K12: =_xlfn.TRANSLATE(A12,"de", "en") -> Key figures for PV systems | N12: =_xlfn.TRANSLATE(F12,"de","en") -> Key figures for PV systems and battery storage systems
G13: PVA und Batterie | H13: nur Batterie | K13: =_xlfn.TRANSLATE(A13,"de", "en") | N13: =_xlfn.TRANSLATE(F13,"de","en") | O13: =_xlfn.TRANSLATE(G13,"de","en") -> PVA and battery | P13: =_xlfn.TRANSLATE(H13,"de","en") -> Battery only
A14: kWh-Kosten (Gestehungskosten) | B14: =IF(_Anlagenleistung=0,"--",-1*(_Summe_Betrieb_Unterhalt+_Summe_MWSt_Umsatz+_Summe_MWSt_Betrieb_Unterhalt+_Summe_Eigenkapital+_Summe_FK1+_Summe_FK2)/_Gesamtenergieertrag) -> 0.30068889 | C14: CHF/kWh | F14: kWh-Kosten (Gestehungskosten) | G14: =IF(_Speicherkapazität=0,"--",-1*(_Summe_Betrieb_Unterhalt+_Summe_Betrieb_Unterhalt_Batterie+_Summe_MWSt_Umsatz+_Summe_MWSt_Betrieb_Unterhalt+_Summe_MWSt_Betrieb_Unterhalt_Batterie+_Summe_Eigenkapital+_Summe_Eigenkapital_Batterie+_Summe_FK1+_Summe_FK2+_Summe_FK1_Batterie)/_Gesamtenergieertrag) -> -- | H14: =IF(_Speicherkapazität=0,"--",-1*(_Summe_Betrieb_Unterhalt_Batterie+_Summe_MWSt_Betrieb_Unterhalt_Batterie+_Summe_Eigenkapital_Batterie+_Summe_FK1_Batterie)/_Gesamtspeichermenge) -> -- | I14: CHF/kWh | K14: =_xlfn.TRANSLATE(A14,"de", "en") -> kWh costs (production costs) | N14: =_xlfn.TRANSLATE(F14,"de","en") -> kWh costs (production costs)
A15: Payback (dyn. Amortisationsrechnung) | B15: =IF(_Amortisationszeit>0,_Amortisationszeit,"--") -> -- | C15: Jahre | F15: Payback (dyn. Amortisationsrechnung) | G15: =IF(_Amortisationszeit_PVA_Batterie>0,_Amortisationszeit_PVA_Batterie,"--") -> -- | H15: =IF(_Amortisationszeit_Batterie>0,_Amortisationszeit_Batterie,"--") -> -- | I15: Jahre | K15: =_xlfn.TRANSLATE(A15,"de", "en") -> Payback (dyn. amortization calculation) | N15: =_xlfn.TRANSLATE(F15,"de","en") -> Payback (dyn. amortization calculation)
A16: Kapitalbarwert (NPV mit Annuität) | B16: =IF(_Anlagenleistung>0,_NPV,"--") -> -18880.846 | C16: CHF | F16: Kapitalbarwert (NPV mit Annuität) | G16: =_NPV_PVA_Batterie -> -18880.846 | H16: =_NPV_Batterie -> 0 | I16: CHF | K16: =_xlfn.TRANSLATE(A16,"de", "en") -> Net present value (NPV with annuity) | N16: =_xlfn.TRANSLATE(F16,"de","en") -> Net present value (NPV with annuity)
A17: Projektrendite (Project IRR) | B17: =IF(ISNUMBER(IRR(Berechnungen!BN7:BN52)*100),IF(IRR(Berechnungen!BN7:BN52)*100>0,IRR(Berechnungen!BN7:BN52)*100,"--"),"--") -> -- | C17: % | F17: Projektrendite (Project IRR) | G17: =IF(ISNUMBER(IRR(Berechnungen!BT7:BT52)*100),IF(IRR(Berechnungen!BT7:BT52)*100>0,IRR(Berechnungen!BT7:BT52)*100,"--"),"--") -> -- | H17: =IF(ISNUMBER(IRR(Berechnungen!BZ7:BZ52)),IF(IRR(Berechnungen!BZ7:BZ52)*100>0,IRR(Berechnungen!BZ7:BZ52)*100,"--"),"--") -> -- | I17: % | K17: =_xlfn.TRANSLATE(A17,"de", "en") -> Project ROI (Project IRR) | N17: =_xlfn.TRANSLATE(F17,"de","en") -> Project ROI (Project IRR)
A18: Eigenkapitalrendite (Equity IRR) | B18: =IF(IRR(Berechnungen!BM7:BM52)*100>0,IRR(Berechnungen!BM7:BM52)*100,"--") -> #NUM! | C18: % | F18: Eigenkapitalrendite (Equity IRR) | G18: =IF(IRR(Berechnungen!BS7:BS52)*100>0,IRR(Berechnungen!BS7:BS52)*100,"--") -> #NUM! | H18: =IF(IRR(Berechnungen!BY7:BY52)*100>0,IRR(Berechnungen!BY7:BY52)*100,"--") -> #NUM! | I18: % | K18: =_xlfn.TRANSLATE(A18,"de", "en") -> Return on equity (IRR) | N18: =_xlfn.TRANSLATE(F18,"de","en") -> Return on equity (IRR)
K19: =_xlfn.TRANSLATE(A19,"de", "en") | N19: =_xlfn.TRANSLATE(F19,"de","en")
A20: Durchschnittswerte PV- Anlage | F20: Durchschnittswerte Batteriespeicher | K20: =_xlfn.TRANSLATE(A20,"de", "en") -> Average values PV system | N20: =_xlfn.TRANSLATE(F20,"de","en") -> Average values battery storage
A21: Ø Jahresenergieertrag | C21: =_Durchschnittlicher_Energieertrag -> 4239 | D21: kWh/Jahr | F21: Ø eingelagerte Energie | H21: =_durchschnittlich_Energie_eingelagert -> #DIV/0! | I21: kWh/Jahr | K21: =_xlfn.TRANSLATE(A21,"de", "en") -> Ø Annual energy yield | N21: =_xlfn.TRANSLATE(F21,"de","en") -> Ø stored energy
A22: ="davon Ø "&(IF(_ZEV="ja","Eigenverbrauch ZEV oder vZEV","Eigenverbrauch")) -> davon Ø Eigenverbrauch ZEV oder vZEV | C22: =_Eigennutzungsgrad/100*_Durchschnittlicher_Energieertrag -> 1410.3333 | D22: kWh/Jahr | F22: ="Ø "&IF(_ZEV=_NEIN,"Einsparung Bezug",IF(_ZEV=_JA,"Stromverkauf ZEV","Fehler")) -> Ø Stromverkauf ZEV | H22: =_Durchschnittlicher_Verkauf_Batteriestrom -> #DIV/0! | I22: CHF/Jahr | K22: =_xlfn.TRANSLATE(A22,"de", "en") -> of which Ø self-consumption ZEV or vZEV | N22: =_xlfn.TRANSLATE(F22,"de","en") -> Ø Electricity sales ZEV
A23: davon Ø Abnahmevergütung | C23: =(1-_Eigennutzungsgrad/100-_Anteil_LEG/100)*_Durchschnittlicher_Energieertrag -> -4.7062354e-13 | D23: kWh/Jahr | F23: ="Ø "&IF(_ZEV=_NEIN,"Einsparung Leistung",IF(_ZEV=_JA,"ZEV Verkauf Batterieleistung","Fehler")) -> Ø ZEV Verkauf Batterieleistung | H23: =_durchschnittliche_Einsparung_Leistung_Batterie -> #DIV/0! | I23: CHF/Jahr | K23: =_xlfn.TRANSLATE(A23,"de", "en") -> of which Ø Purchase remuneration | N23: =_xlfn.TRANSLATE(F23,"de","en") -> Ø ZEV Sale Battery Power
A24: davon Ø an LEG | C24: =_Anteil_LEG/100*_Durchschnittlicher_Energieertrag -> 2828.6667 | D24: kWh/Jahr | F24: Ø Kosten eingelagerte Energie (zum Tarif Abnahmevergütung) | H24: =_durchschnittliche_Kosten_Energie_Speicher -> #DIV/0! | I24: CHF/Jahr | K24: =_xlfn.TRANSLATE(A24,"de", "en") -> of which Ø to LEG | N24: =_xlfn.TRANSLATE(F24,"de","en") -> Ø Costs of stored energy (at the tariff for purchase remuneration)
A25: Ø Abnahmevergütung | C25: =_Durchschnittliche_Vergütung_Rücklieferung -> -4.0447043e-14 | D25: CHF/Jahr | F25: Ø Unterhaltsaufwand und Ersatz | H25: =_Durchschnittliche_Kost_Ersatz_Batterie -> #DIV/0! | I25: CHF/Jahr | K25: =_xlfn.TRANSLATE(A25,"de", "en") -> Ø Purchase remuneration | N25: =_xlfn.TRANSLATE(F25,"de","en") -> Ø Maintenance costs and replacement
A26: ="Ø "&IF(_ZEV=_NEIN,"Einsparung Bezug",IF(_ZEV=_JA,"Stromverkauf ZEV","Fehler")) -> Ø Stromverkauf ZEV | C26: =_Durchschnittlicher_Verkauf_Solarstrom -> 351.50611 | D26: CHF/Jahr | F26: Ø MWST-Vorsteuer (Unterhalt und Ersatz Batteriespeicher) | H26: =_Durchschnittliche_Vorsteuer_Batterieersatz -> #DIV/0! | I26: CHF/Jahr | K26: =_xlfn.TRANSLATE(A26,"de", "en") -> Ø Electricity sales ZEV | N26: =_xlfn.TRANSLATE(F26,"de","en") -> Ø VAT input tax (maintenance and replacement of battery storage)
A27: ="Ø "&IF(_ZEV=_NEIN,"Einsparung Leistung",IF(_ZEV=_JA,"ZEV Verkauf Leistung","Fehler")) -> Ø ZEV Verkauf Leistung | C27: =_durchschnittliche_Einsparung_Leistung -> 0 | D27: CHF/Jahr | F27: Ø Eigenkapitalkosten | H27: =_Durchschnittliche_Eigenkapitalkosten_Batterie -> #DIV/0! | I27: CHF/Jahr | K27: =_xlfn.TRANSLATE(A27,"de", "en") -> Ø ZEV Sales Performance | N27: =_xlfn.TRANSLATE(F27,"de","en") -> Ø Cost of equity
A28: =IF(_ZEV=_NEIN,"",IF(_ZEV=_JA,"Ø ZEV Abrechnungsgebühren","Fehler")) -> Ø ZEV Abrechnungsgebühren | C28: =IF(_ZEV="NEIN","",_Durchschnittlicher_Abrechnungsgebühren_ZEV) -> 0 | D28: =IF(_ZEV="NEIN","","CHF/Jahr") -> CHF/Jahr | F28: Ø Fremdkapitalkosten | H28: =_Durchschnittlicher_Zins_FK_Batterie -> #DIV/0! | I28: CHF/Jahr | K28: =_xlfn.TRANSLATE(A28,"de", "en") -> Ø ZEV Billing Fees | N28: =_xlfn.TRANSLATE(F28,"de","en") -> Ø Borrowing costs
A29: =IF(_LEG=_NEIN,"",IF(_LEG=_JA,"Ø Stromverkauf LEG (inkl. Abrechnungsgebühr)","Fehler")) -> Ø Stromverkauf LEG (inkl. Abrechnungsgebühr) | C29: =IF(_LEG="NEIN","",_durchschnittlicher_Verkauf_LEG) -> 293.75257 | D29: =IF(_LEG="NEIN","","CHF/Jahr") -> CHF/Jahr | F29: Ø Nettoertrag Batteriespeicher | H29: =SUM(H22:H28) -> #DIV/0! | I29: CHF/Jahr | K29: =_xlfn.TRANSLATE(A29,"de", "en") -> Ø Electricity sale LEG (incl. billing fee) | N29: =_xlfn.TRANSLATE(F29,"de","en") -> Ø Net yield battery storage
A30: =IF(_ZEV=_NEIN,"",IF(_ZEV=_JA,"Ø Betriebs- und Abrechnungskosten ZEV","Fehler")) -> Ø Betriebs- und Abrechnungskosten ZEV | C30: =IF(_ZEV="NEIN","",_Durchschnittliche_Betriebskosten_ZEV) -> 0 | D30: =IF(_ZEV="NEIN","","CHF/Jahr") -> CHF/Jahr | K30: =_xlfn.TRANSLATE(A30,"de", "en") -> Ø Operating and billing costs ZEV | N30: =_xlfn.TRANSLATE(F30,"de","en")
A31: =IF(_LEG=_NEIN,"",IF(_LEG=_JA,"Ø Betriebs- und Abrechnungskosten LEG","Fehler")) -> Ø Betriebs- und Abrechnungskosten LEG | C31: =IF(_LEG="NEIN","",_Durchschnittliche_Betriebskosten_LEG) -> 0 | D31: =IF(_LEG="NEIN","","CHF/Jahr") -> CHF/Jahr | K31: =_xlfn.TRANSLATE(A31,"de", "en") -> Ø Operating and billing costs LEG | N31: =_xlfn.TRANSLATE(F31,"de","en")
A32: Ø Unterhaltsaufwand | C32: =_Durchschnittliche_Unterhaltskosten -> -830.41735 | D32: CHF/Jahr | K32: =_xlfn.TRANSLATE(A32,"de", "en") -> Ø Maintenance costs | N32: =_xlfn.TRANSLATE(F32,"de","en")
A33: Ø MWST-Umsatzsteuer (Abnahmevergütung) | C33: =_Durchschnittliche_Umsatzsteuer -> 3.2762105e-15 | D33: CHF/Jahr | K33: =_xlfn.TRANSLATE(A33,"de", "en") -> Ø VAT (purchase remuneration) | N33: =_xlfn.TRANSLATE(F33,"de","en")
A34: Ø MWST-Vorsteuer (Unterhaltskosten) | C34: =_Durchschnittliche_Vorsteuer_Unterhalt -> 67.263805 | D34: CHF/Jahr | K34: =_xlfn.TRANSLATE(A34,"de", "en") -> Ø VAT input tax (maintenance costs) | N34: =_xlfn.TRANSLATE(F34,"de","en")
A35: Ø Eigenkapitalkosten | C35: =_Durchschnittliche_Eigenkapitalkosten -> -511.46667 | D35: CHF/Jahr | K35: =_xlfn.TRANSLATE(A35,"de", "en") -> Ø Cost of equity | N35: =_xlfn.TRANSLATE(F35,"de","en")
A36: Ø Fremdkapitalkosten | C36: =_Durchschnittlicher_Zins_FK1+_Durchschnittlicher_Zins_FK2 -> 0 | D36: CHF/Jahr | K36: =_xlfn.TRANSLATE(A36,"de", "en") -> Ø Borrowing costs | N36: =_xlfn.TRANSLATE(F36,"de","en")
A37: Ø Nettoertrag PV- Anlage | C37: =SUM(C25:C36) -> -629.36154 | D37: CHF/Jahr | F37: Teuerungsrate (für Tarife und Unterhaltskosten) | H37: =_Teuerungsrate -> 0.5 | I37: %/Jahr | K37: =_xlfn.TRANSLATE(A37,"de", "en") -> Ø Net yield of PV system | N37: =_xlfn.TRANSLATE(F37,"de","en") -> Inflation rate (for tariffs and maintenance costs)
K38: =_xlfn.TRANSLATE(A38,"de", "en") | N38: =_xlfn.TRANSLATE(F38,"de","en")
A39: Anlagedaten | K39: =_xlfn.TRANSLATE(A39,"de", "en") -> System data | N39: =_xlfn.TRANSLATE(F39,"de","en")
A40: Anlagekategorie | B40: =_Anlagekategorie -> Dach integriert | K40: =_xlfn.TRANSLATE(A40,"de", "en") -> Investment category | N40: =_xlfn.TRANSLATE(F40,"de","en")
...

Sheet Details
A1: Projektangaben
A2: Projektbezeichnung: | B2: =_Projektbezeichnung&", "&_Standort -> ,
A3: Projektnummer: | B3: =IF(ISNUMBER(_Projektnummer),_Projektnummer,"") | E3: Projektleiter: | G3: =IF(_Projektleiter<>"",_Projektleiter,"")
A4: Betreiber: | B4: =IF(_Betreiber<>"",_Betreiber,"") | E4: MWSt. Pflicht | G4: =_MWStPflicht -> MWSt. pflichtig
A6: Geldflussplan PV- Anlage (ohne Batteriespeicher) | E6: =_xlfn.TRANSLATE(A6,"de","en") -> Cash flow plan PV system (without battery storage)
A32: Sensitivitätsanalyse der Projektrendite ohne Batteriespeicher | E32: =_xlfn.TRANSLATE(A32,"de","en") -> Sensitivity analysis of the project return on investment without battery storage
D33: Abnahmevergütung
D34: =Eingaben!BB40 -> 0.8 | E34: =Eingaben!BC40 -> 0.9 | F34: =Eingaben!BD40 -> 1 | G34: =Eingaben!BE40 -> 1.1 | H34: =Eingaben!BF40 -> 1.2
A35: =_xlfn.TRANSLATE(A36,"de","en") -> Investment PV system | D35: =Eingaben!BB42*100 -> 6.4 | E35: =Eingaben!BC42*100 -> 7.2 | F35: =Eingaben!BD42*100 -> 8 | G35: =Eingaben!BE42*100 -> 8.8 | H35: =Eingaben!BF42*100 -> 9.6
A36: Investitionskosten PV- Anlage | B36: =Eingaben!AZ43 -> 1.2 | C36: =Eingaben!BA43 -> 18412.8 | D36: =IF(ISNUMBER(Eingaben!BB43/100),Eingaben!BB43/100,"--") -> -- | E36: =IF(ISNUMBER(Eingaben!BC43/100),Eingaben!BC43/100,"--") -> -- | F36: =IF(ISNUMBER(Eingaben!BD43/100),Eingaben!BD43/100,"--") -> -- | G36: =IF(ISNUMBER(Eingaben!BE43/100),Eingaben!BE43/100,"--") -> -- | H36: =IF(ISNUMBER(Eingaben!BF43/100),Eingaben!BF43/100,"--") -> --
B37: =Eingaben!AZ44 -> 1.1 | C37: =Eingaben!BA44 -> 16878.4 | D37: =IF(ISNUMBER(Eingaben!BB44/100),Eingaben!BB44/100,"--") -> -- | E37: =IF(ISNUMBER(Eingaben!BC44/100),Eingaben!BC44/100,"--") -> -- | F37: =IF(ISNUMBER(Eingaben!BD44/100),Eingaben!BD44/100,"--") -> -- | G37: =IF(ISNUMBER(Eingaben!BE44/100),Eingaben!BE44/100,"--") -> -- | H37: =IF(ISNUMBER(Eingaben!BF44/100),Eingaben!BF44/100,"--") -> --
B38: =Eingaben!AZ45 -> 1 | C38: =Eingaben!BA45 -> 15344 | D38: =IF(ISNUMBER(Eingaben!BB45/100),Eingaben!BB45/100,"--") -> -- | E38: =IF(ISNUMBER(Eingaben!BC45/100),Eingaben!BC45/100,"--") -> -- | F38: =IF(ISNUMBER(Eingaben!BD45/100),Eingaben!BD45/100,"--") -> -- | G38: =IF(ISNUMBER(Eingaben!BE45/100),Eingaben!BE45/100,"--") -> -- | H38: =IF(ISNUMBER(Eingaben!BF45/100),Eingaben!BF45/100,"--") -> --
B39: =Eingaben!AZ46 -> 0.9 | C39: =Eingaben!BA46 -> 13809.6 | D39: =IF(ISNUMBER(Eingaben!BB46/100),Eingaben!BB46/100,"--") -> -- | E39: =IF(ISNUMBER(Eingaben!BC46/100),Eingaben!BC46/100,"--") -> -- | F39: =IF(ISNUMBER(Eingaben!BD46/100),Eingaben!BD46/100,"--") -> -- | G39: =IF(ISNUMBER(Eingaben!BE46/100),Eingaben!BE46/100,"--") -> -- | H39: =IF(ISNUMBER(Eingaben!BF46/100),Eingaben!BF46/100,"--") -> --
B40: =Eingaben!AZ47 -> 0.8 | C40: =Eingaben!BA47 -> 12275.2 | D40: =IF(ISNUMBER(Eingaben!BB47/100),Eingaben!BB47/100,"--") -> -- | E40: =IF(ISNUMBER(Eingaben!BC47/100),Eingaben!BC47/100,"--") -> -- | F40: =IF(ISNUMBER(Eingaben!BD47/100),Eingaben!BD47/100,"--") -> -- | G40: =IF(ISNUMBER(Eingaben!BE47/100),Eingaben!BE47/100,"--") -> -- | H40: =IF(ISNUMBER(Eingaben!BF47/100),Eingaben!BF47/100,"--") -> --
D42: Teuerung auf Energie und Unterhaltskosten
A43: =_xlfn.TRANSLATE(A44,"de","en") -> Lifetime | D43: =Eingaben!BB19/100 -> 0 | E43: =Eingaben!BC19/100 -> 0.005 | F43: =Eingaben!BD19/100 -> 0.01 | G43: =Eingaben!BE19/100 -> 0.02 | H43: =Eingaben!BF19/100 -> 0.03
A44: Lebensdauer | B44: =Eingaben!BA20 -> 25 | D44: =IF(ISNUMBER(Eingaben!BB20/100),Eingaben!BB20/100,"--") -> -- | E44: =IF(ISNUMBER(Eingaben!BC20/100),Eingaben!BC20/100,"--") -> -- | F44: =IF(ISNUMBER(Eingaben!BD20/100),Eingaben!BD20/100,"--") -> -- | G44: =IF(ISNUMBER(Eingaben!BE20/100),Eingaben!BE20/100,"--") -> -- | H44: =IF(ISNUMBER(Eingaben!BF20/100),Eingaben!BF20/100,"--") -> --
B45: =Eingaben!BA21 -> 30 | D45: =IF(ISNUMBER(Eingaben!BB21/100),Eingaben!BB21/100,"--") -> -- | E45: =IF(ISNUMBER(Eingaben!BC21/100),Eingaben!BC21/100,"--") -> -- | F45: =IF(ISNUMBER(Eingaben!BD21/100),Eingaben!BD21/100,"--") -> -- | G45: =IF(ISNUMBER(Eingaben!BE21/100),Eingaben!BE21/100,"--") -> -- | H45: =IF(ISNUMBER(Eingaben!BF21/100),Eingaben!BF21/100,"--") -> --
B46: =Eingaben!BA22 -> 35 | D46: =IF(ISNUMBER(Eingaben!BB22/100),Eingaben!BB22/100,"--") -> -- | E46: =IF(ISNUMBER(Eingaben!BC22/100),Eingaben!BC22/100,"--") -> -- | F46: =IF(ISNUMBER(Eingaben!BD22/100),Eingaben!BD22/100,"--") -> -- | G46: =IF(ISNUMBER(Eingaben!BE22/100),Eingaben!BE22/100,"--") -> -- | H46: =IF(ISNUMBER(Eingaben!BF22/100),Eingaben!BF22/100,"--") -> --
B47: =Eingaben!BA23 -> 40 | D47: =IF(ISNUMBER(Eingaben!BB23/100),Eingaben!BB23/100,"--") -> -- | E47: =IF(ISNUMBER(Eingaben!BC23/100),Eingaben!BC23/100,"--") -> -- | F47: =IF(ISNUMBER(Eingaben!BD23/100),Eingaben!BD23/100,"--") -> -- | G47: =IF(ISNUMBER(Eingaben!BE23/100),Eingaben!BE23/100,"--") -> -- | H47: =IF(ISNUMBER(Eingaben!BF23/100),Eingaben!BF23/100,"--") -> --
D49: =IF(_ZEV=_NEIN,"ersetzter Bezugstarif ",IF(_ZEV=_JA,"PV- Stromtarif ZEV ","Fehler"))&CHAR(10)&Eingaben!E47 -> PV- Stromtarif ZEV (exkl. MWSt.)
D50: =Eingaben!BB29 -> 0.8 | E50: =Eingaben!BC29 -> 0.9 | F50: =Eingaben!BD29 -> 1 | G50: =Eingaben!BE29 -> 1.1 | H50: =Eingaben!BF29 -> 1.2
A51: =_xlfn.TRANSLATE(A52,"de","en") -> Self-consumption without battery storage | D51: =Eingaben!BB30*100 -> 18.56 | E51: =Eingaben!BC30*100 -> 20.88 | F51: =Eingaben!BD30*100 -> 23.2 | G51: =Eingaben!BE30*100 -> 25.52 | H51: =Eingaben!BF30*100 -> 27.84
A52: Eigenverbrauch ohne Batteriespeicher | B52: =Eingaben!BA31/100 -> 0.23270424 | D52: =IF(ISNUMBER(Eingaben!BB31/100),Eingaben!BB31/100,"--") -> -- | E52: =IF(ISNUMBER(Eingaben!BC31/100),Eingaben!BC31/100,"--") -> -- | F52: =IF(ISNUMBER(Eingaben!BD31/100),Eingaben!BD31/100,"--") -> -- | G52: =IF(ISNUMBER(Eingaben!BE31/100),Eingaben!BE31/100,"--") -> -- | H52: =IF(ISNUMBER(Eingaben!BF31/100),Eingaben!BF31/100,"--") -> --
B53: =Eingaben!BA32/100 -> 0.28270424 | D53: =IF(ISNUMBER(Eingaben!BB32/100),Eingaben!BB32/100,"--") -> -- | E53: =IF(ISNUMBER(Eingaben!BC32/100),Eingaben!BC32/100,"--") -> -- | F53: =IF(ISNUMBER(Eingaben!BD32/100),Eingaben!BD32/100,"--") -> -- | G53: =IF(ISNUMBER(Eingaben!BE32/100),Eingaben!BE32/100,"--") -> -- | H53: =IF(ISNUMBER(Eingaben!BF32/100),Eingaben!BF32/100,"--") -> --
B54: =Eingaben!BA33/100 -> 0.33270424 | D54: =IF(ISNUMBER(Eingaben!BB33/100),Eingaben!BB33/100,"--") -> -- | E54: =IF(ISNUMBER(Eingaben!BC33/100),Eingaben!BC33/100,"--") -> -- | F54: =IF(ISNUMBER(Eingaben!BD33/100),Eingaben!BD33/100,"--") -> -- | G54: =IF(ISNUMBER(Eingaben!BE33/100),Eingaben!BE33/100,"--") -> -- | H54: =IF(ISNUMBER(Eingaben!BF33/100),Eingaben!BF33/100,"--") -> --
B55: =Eingaben!BA34/100 -> 0.38270424 | D55: =IF(ISNUMBER(Eingaben!BB34/100),Eingaben!BB34/100,"--") -> -- | E55: =IF(ISNUMBER(Eingaben!BC34/100),Eingaben!BC34/100,"--") -> -- | F55: =IF(ISNUMBER(Eingaben!BD34/100),Eingaben!BD34/100,"--") -> -- | G55: =IF(ISNUMBER(Eingaben!BE34/100),Eingaben!BE34/100,"--") -> -- | H55: =IF(ISNUMBER(Eingaben!BF34/100),Eingaben!BF34/100,"--") -> --
B56: =Eingaben!BA35/100 -> 0.43270424 | D56: =IF(ISNUMBER(Eingaben!BB35/100),Eingaben!BB35/100,"--") -> -- | E56: =IF(ISNUMBER(Eingaben!BC35/100),Eingaben!BC35/100,"--") -> -- | F56: =IF(ISNUMBER(Eingaben!BD35/100),Eingaben!BD35/100,"--") -> -- | G56: =IF(ISNUMBER(Eingaben!BE35/100),Eingaben!BE35/100,"--") -> -- | H56: =IF(ISNUMBER(Eingaben!BF35/100),Eingaben!BF35/100,"--") -> --
A58: Sensitivitätsanalyse der Projektrendite PV- Anlage mit Batteriespeicher | E58: =_xlfn.TRANSLATE(A58,"de","en") -> Sensitivity analysis of the project return on PV system with battery storage
D59: =IF(_ZEV=_NEIN,"ersetzter Bezugstarif ",IF(_ZEV=_JA,"PV- Stromtarif ZEV ","Fehler"))&CHAR(10)&Eingaben!E47 -> PV- Stromtarif ZEV (exkl. MWSt.)
D60: =Eingaben!BB55 -> 0.8 | E60: =Eingaben!BC55 -> 0.9 | F60: =Eingaben!BD55 -> 1 | G60: =Eingaben!BE55 -> 1.1 | H60: =Eingaben!BF55 -> 1.2
A61: =_xlfn.TRANSLATE(A62,"de","en") -> Investment Battery storage | D61: =Eingaben!BB56*100 -> 18.56 | E61: =Eingaben!BC56*100 -> 20.88 | F61: =Eingaben!BD56*100 -> 23.2 | G61: =Eingaben!BE56*100 -> 25.52 | H61: =Eingaben!BF56*100 -> 27.84
A62: Investitionskosten Batteriespeicher | B62: =Eingaben!AZ57 -> 1.2 | C62: =Eingaben!BA57 -> 0 | D62: =IF(ISNUMBER(Eingaben!BB57/100),Eingaben!BB57/100,"--") -> -- | E62: =IF(ISNUMBER(Eingaben!BC57/100),Eingaben!BC57/100,"--") -> -- | F62: =IF(ISNUMBER(Eingaben!BD57/100),Eingaben!BD57/100,"--") -> -- | G62: =IF(ISNUMBER(Eingaben!BE57/100),Eingaben!BE57/100,"--") -> -- | H62: =IF(ISNUMBER(Eingaben!BF57/100),Eingaben!BF57/100,"--") -> --
B63: =Eingaben!AZ58 -> 1.1 | C63: =Eingaben!BA58 -> 0 | D63: =IF(ISNUMBER(Eingaben!BB58/100),Eingaben!BB58/100,"--") -> -- | E63: =IF(ISNUMBER(Eingaben!BC58/100),Eingaben!BC58/100,"--") -> -- | F63: =IF(ISNUMBER(Eingaben!BD58/100),Eingaben!BD58/100,"--") -> -- | G63: =IF(ISNUMBER(Eingaben!BE58/100),Eingaben!BE58/100,"--") -> -- | H63: =IF(ISNUMBER(Eingaben!BF58/100),Eingaben!BF58/100,"--") -> --
B64: =Eingaben!AZ59 -> 1 | C64: =Eingaben!BA59 -> 0 | D64: =IF(ISNUMBER(Eingaben!BB59/100),Eingaben!BB59/100,"--") -> -- | E64: =IF(ISNUMBER(Eingaben!BC59/100),Eingaben!BC59/100,"--") -> -- | F64: =IF(ISNUMBER(Eingaben!BD59/100),Eingaben!BD59/100,"--") -> -- | G64: =IF(ISNUMBER(Eingaben!BE59/100),Eingaben!BE59/100,"--") -> -- | H64: =IF(ISNUMBER(Eingaben!BF59/100),Eingaben!BF59/100,"--") -> --
B65: =Eingaben!AZ60 -> 0.9 | C65: =Eingaben!BA60 -> 0 | D65: =IF(ISNUMBER(Eingaben!BB60/100),Eingaben!BB60/100,"--") -> -- | E65: =IF(ISNUMBER(Eingaben!BC60/100),Eingaben!BC60/100,"--") -> -- | F65: =IF(ISNUMBER(Eingaben!BD60/100),Eingaben!BD60/100,"--") -> -- | G65: =IF(ISNUMBER(Eingaben!BE60/100),Eingaben!BE60/100,"--") -> -- | H65: =IF(ISNUMBER(Eingaben!BF60/100),Eingaben!BF60/100,"--") -> --
B66: =Eingaben!AZ61 -> 0.8 | C66: =Eingaben!BA61 -> 0 | D66: =IF(ISNUMBER(Eingaben!BB61/100),Eingaben!BB61/100,"--") -> -- | E66: =IF(ISNUMBER(Eingaben!BC61/100),Eingaben!BC61/100,"--") -> -- | F66: =IF(ISNUMBER(Eingaben!BD61/100),Eingaben!BD61/100,"--") -> -- | G66: =IF(ISNUMBER(Eingaben!BE61/100),Eingaben!BE61/100,"--") -> -- | H66: =IF(ISNUMBER(Eingaben!BF61/100),Eingaben!BF61/100,"--") -> --
A68: Sensitivitätsanalyse der Projektrendite nur Batteriespeicher | E68: =_xlfn.TRANSLATE(A68,"de","en") -> Sensitivity analysis of the project return on battery storage only
D69: =IF(_ZEV=_NEIN,"ersetzter Bezugstarif ",IF(_ZEV=_JA,"PV- Stromtarif ZEV ","Fehler"))&CHAR(10)&Eingaben!E47 -> PV- Stromtarif ZEV (exkl. MWSt.)
D70: =Eingaben!BB64 -> 0.8 | E70: =Eingaben!BC64 -> 0.9 | F70: =Eingaben!BD64 -> 1 | G70: =Eingaben!BE64 -> 1.1 | H70: =Eingaben!BF64 -> 1.2
...

Sheet Eingaben
A1: Eingaben Wirtschaftlichkeitsberechnung | B1: Mindestens notwendige Definitionen für eine Berechnung | I1: HS Defaultwert 1 | J1: HS Defaultwert 2 | K1: HS Minimalwert | L1: HS Maximalwert | N1: gewähltes Beispiel | O1: =_xlfn.TRANSLATE(N1,"de","en") -> Example chosen | Q1: =Listen!G4 -> Beispiel 1 | T1: =Listen!G5 -> Beispiel 2 | W1: =Listen!G6 -> Beispiel 3 | Z1: =Listen!G7 -> Beispiel 4 | AC1: =Listen!G8 -> Beispiel 5 | AF1: =Listen!G9 -> Beispiel 6 | AI1: =Listen!G10 -> Beispiel 7 | AL1: =Listen!G11 -> Beispiel 8 | AQ1: =_xlfn.TRANSLATE(A1,"de","en") -> Inputs Profitability Calculation | AY1: HS Sensitivitätsanalyse
A2: =IF(_Debug_Modus=_JA,"DEBUG MODUS AKTIV","") | I2: =_xlfn.TRANSLATE(I1,"de","en") -> HS Default Value 1 | J2: =_xlfn.TRANSLATE(J1,"de","en") -> HS Default Value 2 | K2: =_xlfn.TRANSLATE(K1,"de","en") -> HS Minimum Value | L2: =_xlfn.TRANSLATE(L1,"de","en") -> HS Maximum Value | N2: Aktivierung Debug Modus mit Beispielen | O2: NEIN | R2: =Q1 -> Beispiel 1 | U2: =T1 -> Beispiel 2 | X2: =W1 -> Beispiel 3 | AA2: =Z1 -> Beispiel 4 | AD2: =AC1 -> Beispiel 5 | AG2: =AF1 -> Beispiel 6 | AJ2: =AI1 -> Beispiel 7 | AM2: =AL1 -> Beispiel 8 | AQ2: =_xlfn.TRANSLATE(A2,"de","en")
A3: Projektangaben | I3: =_xlfn.TRANSLATE(A3,"de","en") -> Project information | N3: Auswahl vom Beispiel | O3: Beispiel 4 | S3: =R2 -> Beispiel 1 | V3: =U2 -> Beispiel 2 | Y3: =X2 -> Beispiel 3 | AB3: =AA2 -> Beispiel 4 | AE3: =AD2 -> Beispiel 5 | AH3: =AG2 -> Beispiel 6 | AK3: =AJ2 -> Beispiel 7 | AN3: =AM2 -> Beispiel 8 | AQ3: =_xlfn.TRANSLATE(A3,"de","en") -> Project information
A4: Betreiber / Investor | I4: =_xlfn.TRANSLATE(A4,"de","en") -> Operator / Investor | N4: =_xlfn.TRANSLATE(N3,"de","en") -> Selection of the example | AQ4: =_xlfn.TRANSLATE(A4,"de","en") -> Operator / Investor
A5: MWSt. pflichtig | B5: MWSt. pflichtig | F5: 8.1 | G5: % MWSt. | I5: =_xlfn.TRANSLATE(A5,"de","en") -> Subject to VAT | AQ5: =_xlfn.TRANSLATE(A5,"de","en") -> Subject to VAT
A6: Standort | I6: =_xlfn.TRANSLATE(A6,"de","en") -> Location | AQ6: =_xlfn.TRANSLATE(A6,"de","en") -> Location
A7: Projektbezeichnung | I7: =_xlfn.TRANSLATE(A7,"de","en") -> Project name | AQ7: =_xlfn.TRANSLATE(A7,"de","en") -> Project name
A8: Projektnummer | I8: =_xlfn.TRANSLATE(A8,"de","en") -> Project number | AQ8: =_xlfn.TRANSLATE(A8,"de","en") -> Project number
A9: Projektleiter | I9: =_xlfn.TRANSLATE(A9,"de","en") -> Project manager | AQ9: =_xlfn.TRANSLATE(A9,"de","en") -> Project manager
A10: Netzbetreiber | I10: =_xlfn.TRANSLATE(A10,"de","en") -> Common carrier | AQ10: =_xlfn.TRANSLATE(A10,"de","en") -> Common carrier
A11: Bemerkungen | I11: =_xlfn.TRANSLATE(A11,"de","en") -> Remarks | Q11: Dachsanierung Schrägdach 10 kWp mit Speicher, ohne ZEV, ohne LEG | T11: Dachsanierung Schrägdach 10 kWp ohne Speicher, ohne ZEV, ohne LEG | W11: Flachdach 90 kWp mit Speicher, ohne ZEV, ohne LEG | Z11: Flachdach 90 kWp ohne Speicher, mit ZEV, ohne LEG | AC11: Flachdach 90 kWp mit Speicher, mit ZEV, mit LEG | AQ11: =_xlfn.TRANSLATE(A11,"de","en") -> Remarks
A12: Teuerungsrate (inflation rate) | B12: 0.5 | C12: =IF(B12="",I12,B12) -> 0.5 | D12: %/Jahr | E12: (Wird angewendet auf alle jährlichen Einnahmen und Ausgaben) (Applies to all annual income and expenses) | I12: 0.5 | AQ12: =_xlfn.TRANSLATE(A12,"de","en") -> Inflation rate
AQ13: =_xlfn.TRANSLATE(A13,"de","en")
B14: Eingabewert | C14: Rechenwert | AQ14: =_xlfn.TRANSLATE(A14,"de","en") | AU14: Beschreibung des vorgeschlagenen Rechenwertes | AW14: =_xlfn.TRANSLATE(AU14,"de","en") -> Description of the proposed calculation value
A15: Anlagedaten PVA | E15: Hilfsberechnung über Modulleistung | H15: =_xlfn.TRANSLATE(E15,"De","En") -> Auxiliary calculation via module power | N15: =IF(_xlfn.XLOOKUP($O$3,$Q$1:$AN$1,Q15:AN15,"-",0,1)<>"",_xlfn.XLOOKUP($O$3,$Q$1:$AN$1,Q15:AN15,"-",0,1),"") | O15: =IF(_xlfn.XLOOKUP($O$3,$Q$2:$AN$2,Q15:AN15,"-",0,1)<>"",_xlfn.XLOOKUP($O$3,$Q$2:$AN$2,Q15:AN15,"-",0,1),"") | P15: =IF(_xlfn.XLOOKUP($O$3,$Q$3:$AN$3,Q15:AN15,"-",0,1)<>"",_xlfn.XLOOKUP($O$3,$Q$3:$AN$3,Q15:AN15,"-",0,1),"") | AQ15: =_xlfn.TRANSLATE(A15,"de","en") -> System data PVA | AW15: =_xlfn.TRANSLATE(AU15,"de","en") | AY15: Sensitivitätsanalyse Laufzeit und Teuerung [%]
A16: Anlagekategorie | B16: Dach integriert | E16: Anzahl (number) | F16: Leistung (Wp) | G16: (Resultat wird als Rechenwert für die Anlagenleistung übernommen) | N16: =IF(_xlfn.XLOOKUP($O$3,$Q$1:$AN$1,Q16:AN16,"-",0,1)<>"",_xlfn.XLOOKUP($O$3,$Q$1:$AN$1,Q16:AN16,"-",0,1),"") -> Dach Angebaut | O16: =IF(_xlfn.XLOOKUP($O$3,$Q$2:$AN$2,Q16:AN16,"-",0,1)<>"",_xlfn.XLOOKUP($O$3,$Q$2:$AN$2,Q16:AN16,"-",0,1),"") | P16: =IF(_xlfn.XLOOKUP($O$3,$Q$3:$AN$3,Q16:AN16,"-",0,1)<>"",_xlfn.XLOOKUP($O$3,$Q$3:$AN$3,Q16:AN16,"-",0,1),"") | Q16: Dach Angebaut | T16: Dach Integriert | W16: Dach Angebaut | Z16: Dach Angebaut | AC16: Dach Angebaut | AQ16: =_xlfn.TRANSLATE(A16,"de","en") -> Investment category | AW16: =_xlfn.TRANSLATE(AU16,"de","en")
A17: Anlagenennleistung | C17: =IF(B17="",IF(AND(_Debug_Modus=_JA,N17<>""),N17,I17),B17) -> 4.5 | D17: kWp | E17: 10 | F17: 450 | G17: =E17*F17/1000 -> 4.5 | I17: =G17 -> 4.5 | N17: =IF(_xlfn.XLOOKUP($O$3,$Q$1:$AN$1,Q17:AN17,"-",0,1)<>"",_xlfn.XLOOKUP($O$3,$Q$1:$AN$1,Q17:AN17,"-",0,1),"") -> 90.16 | O17: =IF(_xlfn.XLOOKUP($O$3,$Q$2:$AN$2,Q17:AN17,"-",0,1)<>"",_xlfn.XLOOKUP($O$3,$Q$2:$AN$2,Q17:AN17,"-",0,1),"") | P17: =IF(_xlfn.XLOOKUP($O$3,$Q$3:$AN$3,Q17:AN17,"-",0,1)<>"",_xlfn.XLOOKUP($O$3,$Q$3:$AN$3,Q17:AN17,"-",0,1),"") | Q17: 10.01 | T17: 10.01 | W17: 90.16 | Z17: 90.16 | AC17: 90.16 | AQ17: =_xlfn.TRANSLATE(A17,"de","en") -> Nominal plant capacity | AW17: =_xlfn.TRANSLATE(AU17,"de","en") | AY17: Projektrendite ohne Batterie in %
A18: Fläche PV- Anlage | C18: =IF(B18="",IF(AND(_Debug_Modus=_JA,N18<>""),N18,I18),B18) -> 18.75 | D18: m2 | I18: =_Anlagenleistung/0.24 -> 18.75 | N18: =IF(_xlfn.XLOOKUP($O$3,$Q$1:$AN$1,Q18:AN18,"-",0,1)<>"",_xlfn.XLOOKUP($O$3,$Q$1:$AN$1,Q18:AN18,"-",0,1),"") | O18: =IF(_xlfn.XLOOKUP($O$3,$Q$2:$AN$2,Q18:AN18,"-",0,1)<>"",_xlfn.XLOOKUP($O$3,$Q$2:$AN$2,Q18:AN18,"-",0,1),"") | P18: =IF(_xlfn.XLOOKUP($O$3,$Q$3:$AN$3,Q18:AN18,"-",0,1)<>"",_xlfn.XLOOKUP($O$3,$Q$3:$AN$3,Q18:AN18,"-",0,1),"") | T18: 50 | AQ18: =_xlfn.TRANSLATE(A18,"de","en") -> Area of PV system | AU18: Fläche wird berechnet mit 240 W/m2 | AW18: =_xlfn.TRANSLATE(AU18,"de","en") -> Area is calculated as 240 W/m2 | BB18: Teuerung auf Energie und Unterhaltskosten [%]
A19: Inbetriebnahmejahr | C19: =IF(IF(B19="",IF(AND(_Debug_Modus=_JA,N19<>""),N19,I19),B19)<K19,K19,IF(IF(B19="",IF(AND(_Debug_Modus=_JA,N19<>""),N19,I19),B19)>L19,L19,IF(B19="",IF(AND(_Debug_Modus=_JA,N19<>""),N19,I19),B19))) -> 2025 | I19: =YEAR(TODAY()) -> 2025 | K19: 2022 | L19: 2100 | N19: =IF(_xlfn.XLOOKUP($O$3,$Q$1:$AN$1,Q19:AN19,"-",0,1)<>"",_xlfn.XLOOKUP($O$3,$Q$1:$AN$1,Q19:AN19,"-",0,1),"") | O19: =IF(_xlfn.XLOOKUP($O$3,$Q$2:$AN$2,Q19:AN19,"-",0,1)<>"",_xlfn.XLOOKUP($O$3,$Q$2:$AN$2,Q19:AN19,"-",0,1),"") | P19: =IF(_xlfn.XLOOKUP($O$3,$Q$3:$AN$3,Q19:AN19,"-",0,1)<>"",_xlfn.XLOOKUP($O$3,$Q$3:$AN$3,Q19:AN19,"-",0,1),"") | AQ19: =_xlfn.TRANSLATE(A19,"de","en") -> Year of commissioning | AU19: immer aktuelles Jahr | AW19: =_xlfn.TRANSLATE(AU19,"de","en") -> always current year | BA19: =_Projektrendite -> -- | BB19: 0 | BC19: 0.5 | BD19: 1 | BE19: 2 | BF19: 3
A20: Anlagenlebensdauer | C20: =IF(IF(B20="",IF(AND(_Debug_Modus=_JA,N20<>""),N20,I20),B20)<K20,K20,IF(IF(B20="",IF(AND(_Debug_Modus=_JA,N20<>""),N20,I20),B20)>L20,L20,IF(B20="",IF(AND(_Debug_Modus=_JA,N20<>""),N20,I20),B20))) -> 30 | D20: Jahre | I20: 30 | K20: 0 | L20: 45 | N20: =IF(_xlfn.XLOOKUP($O$3,$Q$1:$AN$1,Q20:AN20,"-",0,1)<>"",_xlfn.XLOOKUP($O$3,$Q$1:$AN$1,Q20:AN20,"-",0,1),"") -> 25 | O20: =IF(_xlfn.XLOOKUP($O$3,$Q$2:$AN$2,Q20:AN20,"-",0,1)<>"",_xlfn.XLOOKUP($O$3,$Q$2:$AN$2,Q20:AN20,"-",0,1),"") | P20: =IF(_xlfn.XLOOKUP($O$3,$Q$3:$AN$3,Q20:AN20,"-",0,1)<>"",_xlfn.XLOOKUP($O$3,$Q$3:$AN$3,Q20:AN20,"-",0,1),"") | T20: 30 | W20: 25 | Z20: 25 | AC20: 25 | AQ20: =_xlfn.TRANSLATE(A20,"de","en") -> System service life | AU20: Fixe Annahme von 30 Jahren gemäss Erfahrungswerten | AW20: =_xlfn.TRANSLATE(AU20,"de","en") -> Fixed assumption of 30 years according to empirical values | AY20: Laufzeit [Jahre] | BA20: 25 | BB20: -- | BC20: -- | BD20: -- | BE20: -- | BF20: --
A21: spez. Jahresenergieertrag | C21: =IF(B21="",IF(AND(_Debug_Modus=_JA,N21<>""),N21,I21),B21) -> 1000 | D21: kWh/kWp | E21: (Im 1. Betriebsjahr) | I21: =IF(OR(_Anlagekategorie=_Fassade_angebaut,_Anlagekategorie=_Fassade_integriert),800,1000) -> 1000 | N21: =IF(_xlfn.XLOOKUP($O$3,$Q$1:$AN$1,Q21:AN21,"-",0,1)<>"",_xlfn.XLOOKUP($O$3,$Q$1:$AN$1,Q21:AN21,"-",0,1),"") -> 950 | O21: =IF(_xlfn.XLOOKUP($O$3,$Q$2:$AN$2,Q21:AN21,"-",0,1)<>"",_xlfn.XLOOKUP($O$3,$Q$2:$AN$2,Q21:AN21,"-",0,1),"") | P21: =IF(_xlfn.XLOOKUP($O$3,$Q$3:$AN$3,Q21:AN21,"-",0,1)<>"",_xlfn.XLOOKUP($O$3,$Q$3:$AN$3,Q21:AN21,"-",0,1),"") | Q21: 950 | T21: 950 | W21: 950 | Z21: 950 | AC21: 950 | AQ21: =_xlfn.TRANSLATE(A21,"de","en") -> spec. Annual energy yield | AU21: durchschnittlicher spez. Jahresertrag von 1'000 kWh/kWp ohne Berücksichtigung von Standort, Ausrichtung, Neigung und Verschattung | AW21: =_xlfn.TRANSLATE(AU21,"de","en") -> Average Spec. Annual yield of 1,000 kWh/kWp without taking into account location, orientation, inclination and shading | BA21: 30 | BB21: -- | BC21: -- | BD21: -- | BE21: -- | BF21: --
A22: Jahresenergieertrag | C22: =_Anlagenleistung*_spez_Jahresenergieertrag -> 4500 | D22: kWh | E22: (Im 1. Betriebsjahr) | AQ22: =_xlfn.TRANSLATE(A22,"de","en") -> Annual energy yield | AW22: =_xlfn.TRANSLATE(AU22,"de","en") | BA22: 35 | BB22: -- | BC22: -- | BD22: -- | BE22: -- | BF22: --
A23: Degradation | C23: =IF(B23="",IF(AND(_Debug_Modus=_JA,N23<>""),N23,I23),B23) -> 0.4 | D23: %/Jahr | I23: 0.4 | N23: =IF(_xlfn.XLOOKUP($O$3,$Q$1:$AN$1,Q23:AN23,"-",0,1)<>"",_xlfn.XLOOKUP($O$3,$Q$1:$AN$1,Q23:AN23,"-",0,1),"") -> 0.5 | O23: =IF(_xlfn.XLOOKUP($O$3,$Q$2:$AN$2,Q23:AN23,"-",0,1)<>"",_xlfn.XLOOKUP($O$3,$Q$2:$AN$2,Q23:AN23,"-",0,1),"") | P23: =IF(_xlfn.XLOOKUP($O$3,$Q$3:$AN$3,Q23:AN23,"-",0,1)<>"",_xlfn.XLOOKUP($O$3,$Q$3:$AN$3,Q23:AN23,"-",0,1),"") | Q23: 0.6 | T23: 0.6 | W23: 0.5 | Z23: 0.5 | AC23: 0.5 | AQ23: =_xlfn.TRANSLATE(A23,"de","en") -> Degradation | AU23: Entspricht einer Degradation von 10 % in 25 Jahren und liegt im Bereich der Angaben der Modulhersteller (Leistungsgarantie) | AW23: =_xlfn.TRANSLATE(AU23,"de","en") -> Corresponds to a degradation of 10 % in 25 years and is within the range of the specifications of the module manufacturers (performance guarantee) | BA23: 40 | BB23: -- | BC23: -- | BD23: -- | BE23: -- | BF23: --
N24: =IF(_xlfn.XLOOKUP($O$3,$Q$1:$AN$1,Q24:AN24,"-",0,1)<>"",_xlfn.XLOOKUP($O$3,$Q$1:$AN$1,Q24:AN24,"-",0,1),"") | O24: =IF(_xlfn.XLOOKUP($O$3,$Q$2:$AN$2,Q24:AN24,"-",0,1)<>"",_xlfn.XLOOKUP($O$3,$Q$2:$AN$2,Q24:AN24,"-",0,1),"") | P24: =IF(_xlfn.XLOOKUP($O$3,$Q$3:$AN$3,Q24:AN24,"-",0,1)<>"",_xlfn.XLOOKUP($O$3,$Q$3:$AN$3,Q24:AN24,"-",0,1),"") | AQ24: =_xlfn.TRANSLATE(A24,"de","en") | AW24: =_xlfn.TRANSLATE(AU24,"de","en")
A25: Anlagedaten Batteriespeicher | N25: =IF(_xlfn.XLOOKUP($O$3,$Q$1:$AN$1,Q25:AN25,"-",0,1)<>"",_xlfn.XLOOKUP($O$3,$Q$1:$AN$1,Q25:AN25,"-",0,1),"") | O25: =IF(_xlfn.XLOOKUP($O$3,$Q$2:$AN$2,Q25:AN25,"-",0,1)<>"",_xlfn.XLOOKUP($O$3,$Q$2:$AN$2,Q25:AN25,"-",0,1),"") | P25: =IF(_xlfn.XLOOKUP($O$3,$Q$3:$AN$3,Q25:AN25,"-",0,1)<>"",_xlfn.XLOOKUP($O$3,$Q$3:$AN$3,Q25:AN25,"-",0,1),"") | AQ25: =_xlfn.TRANSLATE(A25,"de","en") -> System data battery storage system | AW25: =_xlfn.TRANSLATE(AU25,"de","en") | AY25: Sensitivitätsanalyse Eigenverbrauch und Zuschlag Tarif externer Energiebezug
A26: Batteriespeicher vorhanden | B26: NEIN | C26: =IF(_Debug_Modus=_JA,N26,IF(B26="",I26,B26)) -> NEIN | I26: =_JA -> JA | J26: =_NEIN -> NEIN | N26: =IF(_xlfn.XLOOKUP($O$3,$Q$1:$AN$1,Q26:AN26,"-",0,1)<>"",_xlfn.XLOOKUP($O$3,$Q$1:$AN$1,Q26:AN26,"-",0,1),"") -> NEIN | O26: =IF(_xlfn.XLOOKUP($O$3,$Q$2:$AN$2,Q26:AN26,"-",0,1)<>"",_xlfn.XLOOKUP($O$3,$Q$2:$AN$2,Q26:AN26,"-",0,1),"") | P26: =IF(_xlfn.XLOOKUP($O$3,$Q$3:$AN$3,Q26:AN26,"-",0,1)<>"",_xlfn.XLOOKUP($O$3,$Q$3:$AN$3,Q26:AN26,"-",0,1),"") | Q26: JA | T26: NEIN | W26: JA | Z26: NEIN | AC26: JA | AQ26: =_xlfn.TRANSLATE(A26,"de","en") -> Battery storage available | AW26: =_xlfn.TRANSLATE(AU26,"de","en")
A27: Speichertechnologie | B27: Lithium-Ionen LFP | N27: =IF(_xlfn.XLOOKUP($O$3,$Q$1:$AN$1,Q27:AN27,"-",0,1)<>"",_xlfn.XLOOKUP($O$3,$Q$1:$AN$1,Q27:AN27,"-",0,1),"") | O27: =IF(_xlfn.XLOOKUP($O$3,$Q$2:$AN$2,Q27:AN27,"-",0,1)<>"",_xlfn.XLOOKUP($O$3,$Q$2:$AN$2,Q27:AN27,"-",0,1),"") | P27: =IF(_xlfn.XLOOKUP($O$3,$Q$3:$AN$3,Q27:AN27,"-",0,1)<>"",_xlfn.XLOOKUP($O$3,$Q$3:$AN$3,Q27:AN27,"-",0,1),"") | Q27: Lithium-Ionen LFP | W27: Lithium-Ionen LFP | AQ27: =_xlfn.TRANSLATE(A27,"de","en") -> Storage Technology | AW27: =_xlfn.TRANSLATE(AU27,"de","en")
A28: Speicherkapazität | C28: =IF(_Batterie=_NEIN,0,IF(IF(B28="",IF(AND(_Debug_Modus=_JA,N28<>""),N28,I28),B28)<K28,K28,IF(IF(B28="",IF(AND(_Debug_Modus=_JA,N28<>""),N28,I28),B28)>L28,L28,IF(B28="",IF(AND(_Debug_Modus=_JA,N28<>""),N28,I28),B28)))) -> 0 | D28: kWh | E28: (Nutzkapazität im Inbetriebnahmejahr) | I28: =IF(_Anlagenleistung*_spez_Jahresenergieertrag/1000<_Gesamtverbrauch/1000,_Anlagenleistung*_spez_Jahresenergieertrag/1000,_Gesamtverbrauch/1000) -> 4.5 | K28: 0 | L28: 100000 | N28: =IF(_xlfn.XLOOKUP($O$3,$Q$1:$AN$1,Q28:AN28,"-",0,1)<>"",_xlfn.XLOOKUP($O$3,$Q$1:$AN$1,Q28:AN28,"-",0,1),"") | O28: =IF(_xlfn.XLOOKUP($O$3,$Q$2:$AN$2,Q28:AN28,"-",0,1)<>"",_xlfn.XLOOKUP($O$3,$Q$2:$AN$2,Q28:AN28,"-",0,1),"") | P28: =IF(_xlfn.XLOOKUP($O$3,$Q$3:$AN$3,Q28:AN28,"-",0,1)<>"",_xlfn.XLOOKUP($O$3,$Q$3:$AN$3,Q28:AN28,"-",0,1),"") | Q28: 10 | W28: 105 | AQ28: =_xlfn.TRANSLATE(A28,"de","en") -> Storage capacity | AU28: Der kleinere Wert von 1/1'000 der Jahresproduktion oder 1/1'000 des Jahresenergiebedarfs | AW28: =_xlfn.TRANSLATE(AU28,"de","en") -> The smaller value of 1/1,000 of the annual production or 1/1,000 of the annual energy demand | AY28: Projektrendite ohne Batterie in % | BB28: ersetzter Bezugstarif / PV- Stromtarif ZEV [CHF/kWh]
A29: Wirkungsgrad des Speichers | C29: =IF(IF(B29="",IF(AND(_Debug_Modus=_JA,N29<>""),N29,I29),B29)<K29,K29,IF(IF(B29="",IF(AND(_Debug_Modus=_JA,N29<>""),N29,I29),B29)>L29,L29,IF(B29="",IF(AND(_Debug_Modus=_JA,N29<>""),N29,I29),B29))) -> 90 | D29: % | E29: (typische Werte von Lithium- Ionen Speicher liegen zwischen 85 - 95%) | I29: 90 | K29: 0 | L29: 100 | N29: =IF(_xlfn.XLOOKUP($O$3,$Q$1:$AN$1,Q29:AN29,"-",0,1)<>"",_xlfn.XLOOKUP($O$3,$Q$1:$AN$1,Q29:AN29,"-",0,1),"") | O29: =IF(_xlfn.XLOOKUP($O$3,$Q$2:$AN$2,Q29:AN29,"-",0,1)<>"",_xlfn.XLOOKUP($O$3,$Q$2:$AN$2,Q29:AN29,"-",0,1),"") | P29: =IF(_xlfn.XLOOKUP($O$3,$Q$3:$AN$3,Q29:AN29,"-",0,1)<>"",_xlfn.XLOOKUP($O$3,$Q$3:$AN$3,Q29:AN29,"-",0,1),"") | W29: 88 | AQ29: =_xlfn.TRANSLATE(A29,"de","en") -> Efficiency of the storage system | AU29: Es wird ein Wert in der Mitte des typischen Bereiches verwendet | AW29: =_xlfn.TRANSLATE(AU29,"de","en") -> A value in the middle of the typical range is used | BB29: 0.8 | BC29: 0.9 | BD29: 1 | BE29: 1.1 | BF29: 1.2
A30: Speicherlebensdauer | C30: =IF(IF(B30="",IF(AND(_Debug_Modus=_JA,N30<>""),N30,I30),B30)<K30,K30,IF(IF(B30="",IF(AND(_Debug_Modus=_JA,N30<>""),N30,I30),B30)>L30,L30,IF(B30="",IF(AND(_Debug_Modus=_JA,N30<>""),N30,I30),B30))) -> 15 | E30: (typische Werte von Lithium- Ionen Speicher liegen zwischen 10 - 20 Jahren) | I30: 15 | K30: 0 | L30: =_Anlagenlebensdauer -> 30 | N30: =IF(_xlfn.XLOOKUP($O$3,$Q$1:$AN$1,Q30:AN30,"-",0,1)<>"",_xlfn.XLOOKUP($O$3,$Q$1:$AN$1,Q30:AN30,"-",0,1),"") | O30: =IF(_xlfn.XLOOKUP($O$3,$Q$2:$AN$2,Q30:AN30,"-",0,1)<>"",_xlfn.XLOOKUP($O$3,$Q$2:$AN$2,Q30:AN30,"-",0,1),"") | P30: =IF(_xlfn.XLOOKUP($O$3,$Q$3:$AN$3,Q30:AN30,"-",0,1)<>"",_xlfn.XLOOKUP($O$3,$Q$3:$AN$3,Q30:AN30,"-",0,1),"") | W30: 14 | AQ30: =_xlfn.TRANSLATE(A30,"de","en") -> Storage life | AU30: Es wird ein Wert in der Mitte des typischen Bereiches verwendet | AW30: =_xlfn.TRANSLATE(AU30,"de","en") -> A value in the middle of the typical range is used | BA30: =_Projektrendite -> -- | BB30: =$BD30*BB29 -> 0.1856 | BC30: =$BD30*BC29 -> 0.2088 | BD30: =IF(B47="",IF(AND(_Debug_Modus=_JA,N47<>""),N47,I47),B47) -> 0.232 | BE30: =$BD30*BE29 -> 0.2552 | BF30: =$BD30*BF29 -> 0.2784
A31: Degradation | C31: =IF(IF(B31="",IF(AND(_Debug_Modus=_JA,N31<>""),N31,I31),B31)<K31,K31,IF(IF(B31="",IF(AND(_Debug_Modus=_JA,N31<>""),N31,I31),B31)>L31,L31,IF(B31="",IF(AND(_Debug_Modus=_JA,N31<>""),N31,I31),B31))) -> 1.3333333 | D31: % / Jahr | E31: (Meist wird von 20% Degradation während der Lebensdauer ausgegangen) | I31: =20/I30 -> 1.3333333 | K31: 0 | L31: 10 | N31: =IF(_xlfn.XLOOKUP($O$3,$Q$1:$AN$1,Q31:AN31,"-",0,1)<>"",_xlfn.XLOOKUP($O$3,$Q$1:$AN$1,Q31:AN31,"-",0,1),"") | O31: =IF(_xlfn.XLOOKUP($O$3,$Q$2:$AN$2,Q31:AN31,"-",0,1)<>"",_xlfn.XLOOKUP($O$3,$Q$2:$AN$2,Q31:AN31,"-",0,1),"") | P31: =IF(_xlfn.XLOOKUP($O$3,$Q$3:$AN$3,Q31:AN31,"-",0,1)<>"",_xlfn.XLOOKUP($O$3,$Q$3:$AN$3,Q31:AN31,"-",0,1),"") | W31: 1 | AQ31: =_xlfn.TRANSLATE(A31,"de","en") -> Degradation | AU31: Es wird mit einer Reduktion der Batteriekapazität von 20% innerhalb der Lebensdauer gerechnet | AW31: =_xlfn.TRANSLATE(AU31,"de","en") -> A reduction in battery capacity of 20% is expected within the service life | AY31: Eigenverbrauch [%] | BA31: =IF(BA32-5>0,BA32-5,0) -> 23.270424 | BB31: -- | BC31: -- | BD31: -- | BE31: -- | BF31: --
A32: Eigenverbrauchsanteil mit Batterie | C32: =IF(_Batterie=_NEIN,0,IF(IF(B32="",IF(AND(_Debug_Modus=_JA,N32<>""),N32,I32),B32)<K32,K32,IF(IF(B32="",IF(AND(_Debug_Modus=_JA,N32<>""),N32,I32),B32)>L32,L32,IF(B32="",IF(AND(_Debug_Modus=_JA,N32<>""),N32,I32),B32)))) -> 0 | D32: % | I32: =IF(_Eigennutzungsgrad+20>100,100,_Eigennutzungsgrad+20) -> 53.270424 | K32: 0 | L32: 100 | N32: =IF(_xlfn.XLOOKUP($O$3,$Q$1:$AN$1,Q32:AN32,"-",0,1)<>"",_xlfn.XLOOKUP($O$3,$Q$1:$AN$1,Q32:AN32,"-",0,1),"") | O32: =IF(_xlfn.XLOOKUP($O$3,$Q$2:$AN$2,Q32:AN32,"-",0,1)<>"",_xlfn.XLOOKUP($O$3,$Q$2:$AN$2,Q32:AN32,"-",0,1),"") | P32: =IF(_xlfn.XLOOKUP($O$3,$Q$3:$AN$3,Q32:AN32,"-",0,1)<>"",_xlfn.XLOOKUP($O$3,$Q$3:$AN$3,Q32:AN32,"-",0,1),"") | Q32: 45 | W32: 70 | AQ32: =_xlfn.TRANSLATE(A32,"de","en") -> Self-consumption share with battery | AU32: Es wird mit einer durchschnittlichen Erhöhung des Eigenverbrauchsanteils um 20% gerechnet, was im Wohnbereich ein zu erwartender Wert ist | AW32: =_xlfn.TRANSLATE(AU32,"de","en") -> An average increase in the share of self-consumption of 20% is expected, which is an expected value in the residential area | BA32: =IF(BA33-5>0,BA33-5,0) -> 28.270424 | BB32: -- | BC32: -- | BD32: -- | BE32: -- | BF32: --
A33: Erhöhung Eigenverbrauchsanteil mit Batterie | C33: =IF(IF(B33="",IF(AND(_Debug_Modus=_JA,N33<>""),N33,I33),B33)<K33,K33,IF(IF(B33="",IF(AND(_Debug_Modus=_JA,N33<>""),N33,I33),B33)>L33,L33,IF(B33="",IF(AND(_Debug_Modus=_JA,N33<>""),N33,I33),B33))) -> 0 | D33: % | I33: =C32-_Eigennutzungsgrad -> -33.270424 | K33: 0 | L33: 100 | N33: =IF(_xlfn.XLOOKUP($O$3,$Q$1:$AN$1,Q33:AN33,"-",0,1)<>"",_xlfn.XLOOKUP($O$3,$Q$1:$AN$1,Q33:AN33,"-",0,1),"") | O33: =IF(_xlfn.XLOOKUP($O$3,$Q$2:$AN$2,Q33:AN33,"-",0,1)<>"",_xlfn.XLOOKUP($O$3,$Q$2:$AN$2,Q33:AN33,"-",0,1),"") | P33: =IF(_xlfn.XLOOKUP($O$3,$Q$3:$AN$3,Q33:AN33,"-",0,1)<>"",_xlfn.XLOOKUP($O$3,$Q$3:$AN$3,Q33:AN33,"-",0,1),"") | AQ33: =_xlfn.TRANSLATE(A33,"de","en") -> Increase in self-consumption share with battery | AU33: Wird berechnet aus der Differenz zwischen Eigenverbrauchsanteils mit Batterie und Eigenverbrauchsanteil am Ort der Produktion | AW33: =_xlfn.TRANSLATE(AU33,"de","en") -> Calculated from the difference between the self-consumption share with the battery and the self-consumption share at the place of production | BA33: =IF(IF(B45="",IF(AND(_Debug_Modus=_JA,N45<>""),N45,I45),B45)<K45,K45,IF(IF(B45="",IF(AND(_Debug_Modus=_JA,N45<>""),N45,I45),B45)>L45,L45,IF(B45="",IF(AND(_Debug_Modus=_JA,N45<>""),N45,I45),B45))) -> 33.270424 | BB33: -- | BC33: -- | BD33: -- | BE33: -- | BF33: --
A34: Reduktion der Summe der Leistungsspitzen pro Jahr | C34: =IF(_Batterie=_NEIN,0,IF(IF(B34="",IF(AND(_Debug_Modus=_JA,N34<>""),N34,I34),B34)<K34,K34,IF(IF(B34="",IF(AND(_Debug_Modus=_JA,N34<>""),N34,I34),B34)>L34,L34,IF(B34="",IF(AND(_Debug_Modus=_JA,N34<>""),N34,I34),B34)))) -> 0 | D34: % | E34: (Durch Batteriespeicher reduzierte, abrechnungsrelevante Leistungsspitzen pro Monat über ein Jahr aufsummiert) | I34: 30 | K34: 0 | L34: =100-_Reduktion_Leistungsspitzen -> 100 | N34: =IF(_xlfn.XLOOKUP($O$3,$Q$1:$AN$1,Q34:AN34,"-",0,1)<>"",_xlfn.XLOOKUP($O$3,$Q$1:$AN$1,Q34:AN34,"-",0,1),"") | O34: =IF(_xlfn.XLOOKUP($O$3,$Q$2:$AN$2,Q34:AN34,"-",0,1)<>"",_xlfn.XLOOKUP($O$3,$Q$2:$AN$2,Q34:AN34,"-",0,1),"") | P34: =IF(_xlfn.XLOOKUP($O$3,$Q$3:$AN$3,Q34:AN34,"-",0,1)<>"",_xlfn.XLOOKUP($O$3,$Q$3:$AN$3,Q34:AN34,"-",0,1),"") | Q34: 50 | W34: 40 | AQ34: =_xlfn.TRANSLATE(A34,"de","en") -> Reduction of the sum of power peaks per year | AU34: Es wird mit einer durchschnittlichen Reduktion der Summe der monatlichen Leistungsspitzen für ein Jahr von 30% gerechnet | AW34: =_xlfn.TRANSLATE(AU34,"de","en") -> An average reduction in the sum of monthly performance peaks for one year of 30% is expected | BA34: =IF(BA33+5<=100,BA33+5,100) -> 38.270424 | BB34: -- | BC34: -- | BD34: -- | BE34: -- | BF34: --
AQ35: =_xlfn.TRANSLATE(A35,"de","en") | AW35: =_xlfn.TRANSLATE(AU35,"de","en") | BA35: =IF(BA34+5<=100,BA34+5,100) -> 43.270424 | BB35: -- | BC35: -- | BD35: -- | BE35: -- | BF35: --
A36: Verbrauchsdaten | N36: =IF(_xlfn.XLOOKUP($O$3,$Q$1:$AN$1,Q36:AN36,"-",0,1)<>"",_xlfn.XLOOKUP($O$3,$Q$1:$AN$1,Q36:AN36,"-",0,1),"") | O36: =IF(_xlfn.XLOOKUP($O$3,$Q$2:$AN$2,Q36:AN36,"-",0,1)<>"",_xlfn.XLOOKUP($O$3,$Q$2:$AN$2,Q36:AN36,"-",0,1),"") | P36: =IF(_xlfn.XLOOKUP($O$3,$Q$3:$AN$3,Q36:AN36,"-",0,1)<>"",_xlfn.XLOOKUP($O$3,$Q$3:$AN$3,Q36:AN36,"-",0,1),"") | AQ36: =_xlfn.TRANSLATE(A36,"de","en") -> Consumption | AW36: =_xlfn.TRANSLATE(AU36,"de","en")
A37: Jahresenergieverbrauch | C37: =IF(B37="",IF(AND(_Debug_Modus=_JA,N37<>""),N37,I37),B37) -> 4500 | D37: kWh | E37: (Jahresenergieverbrauch aller Solarstromkonsumenten exkl LEG) | I37: =_Anlagenleistung*_spez_Jahresenergieertrag -> 4500 | N37: =IF(_xlfn.XLOOKUP($O$3,$Q$1:$AN$1,Q37:AN37,"-",0,1)<>"",_xlfn.XLOOKUP($O$3,$Q$1:$AN$1,Q37:AN37,"-",0,1),"") -> 150000 | O37: =IF(_xlfn.XLOOKUP($O$3,$Q$2:$AN$2,Q37:AN37,"-",0,1)<>"",_xlfn.XLOOKUP($O$3,$Q$2:$AN$2,Q37:AN37,"-",0,1),"") | P37: =IF(_xlfn.XLOOKUP($O$3,$Q$3:$AN$3,Q37:AN37,"-",0,1)<>"",_xlfn.XLOOKUP($O$3,$Q$3:$AN$3,Q37:AN37,"-",0,1),"") | Q37: 5000 | T37: 5000 | W37: 70000 | Z37: 150000 | AC37: 150000 | AQ37: =_xlfn.TRANSLATE(A37,"de","en") -> Annual energy consumption | AU37: Es wird von einem Deckungsgrad von 100% ausgegangen, d.h. der Gesamtverbrauch entspricht der Gesamtproduktion | AW37: =_xlfn.TRANSLATE(AU37,"de","en") -> A coverage ratio of 100% is assumed, i.e. total consumption corresponds to total production | AY37: Sensitivitätsanalyse Kosten
A38: Summe der Leistungsspitzen aller Monate | C38: =IF(B38="",IF(AND(_Debug_Modus=_JA,N38<>""),N38,I38),B38) -> 61.643836 | D38: kW | E38: (Abrechnungsrelevante Leistungsspitzen pro Monat über ein Jahr aufsummiert) | I38: =_Gesamtverbrauch/(365*24)*10*12 -> 61.643836 | N38: =IF(_xlfn.XLOOKUP($O$3,$Q$1:$AN$1,Q38:AN38,"-",0,1)<>"",_xlfn.XLOOKUP($O$3,$Q$1:$AN$1,Q38:AN38,"-",0,1),"") -> 2000 | O38: =IF(_xlfn.XLOOKUP($O$3,$Q$2:$AN$2,Q38:AN38,"-",0,1)<>"",_xlfn.XLOOKUP($O$3,$Q$2:$AN$2,Q38:AN38,"-",0,1),"") | P38: =IF(_xlfn.XLOOKUP($O$3,$Q$3:$AN$3,Q38:AN38,"-",0,1)<>"",_xlfn.XLOOKUP($O$3,$Q$3:$AN$3,Q38:AN38,"-",0,1),"") | Q38: 60 | T38: 60 | W38: 1000 | Z38: 2000 | AC38: 2000 | AQ38: =_xlfn.TRANSLATE(A38,"de","en") -> Sum of power peaks of all months | AU38: Es wird der mittlere stündliche Energiebedarf ermittelt und mit dem Faktor 10 multipliziert. Dieser Wert wird für jeden Monat als Leistungsspitze angenommen | AW38: =_xlfn.TRANSLATE(AU38,"de","en") -> The average hourly energy requirement is determined and multiplied by a factor of 10. This value is assumed to be the performance peak for each month
AQ39: =_xlfn.TRANSLATE(A39,"de","en") | AW39: =_xlfn.TRANSLATE(AU39,"de","en") | AY39: Projektrendite ohne Batterie in % | BB39: Abnahmevergütung [CHF/kWh]
N40: =IF(_xlfn.XLOOKUP($O$3,$Q$1:$AN$1,Q40:AN40,"-",0,1)<>"",_xlfn.XLOOKUP($O$3,$Q$1:$AN$1,Q40:AN40,"-",0,1),"") | O40: =IF(_xlfn.XLOOKUP($O$3,$Q$2:$AN$2,Q40:AN40,"-",0,1)<>"",_xlfn.XLOOKUP($O$3,$Q$2:$AN$2,Q40:AN40,"-",0,1),"") | P40: =IF(_xlfn.XLOOKUP($O$3,$Q$3:$AN$3,Q40:AN40,"-",0,1)<>"",_xlfn.XLOOKUP($O$3,$Q$3:$AN$3,Q40:AN40,"-",0,1),"") | AQ40: =_xlfn.TRANSLATE(A40,"de","en") | AW40: =_xlfn.TRANSLATE(AU40,"de","en") | BB40: 0.8 | BC40: 0.9 | BD40: 1 | BE40: 1.1 | BF40: 1.2
...

Sheet Berechnungen
A1: Geldflusstabelle | C1: HS | E1: HS | F1: HS | G1: HS | H1: HS | J1: HS | L1: HS | O1: HS | P1: HS | R1: HS | T1: HS | V1: HS | X1: HS | Z1: HS | AA1: HS | AF1: HS | AG1: HS | AH1: HS | AI1: HS | AJ1: HS | AK1: HS | AL1: HS | AM1: HS | AN1: HS | AO1: HS | AQ1: HS | AR1: HS | AS1: HS | AT1: HS | AU1: HS | AV1: HS | AW1: HS | BF1: HS | BG1: HS | BN1: HS | BR1: HS | BT1: HS | BX1: HS | BZ1: HS | CD1: HS
AF2: =Eingaben!A114 -> Kontrollgänge | AG2: =Eingaben!A115 -> Audits / Sicherheitsnachweise | AH2: =Eingaben!A116 -> Überwachung | AI2: =Eingaben!A117 -> Administration | AJ2: =Eingaben!A118 -> Datenverbindung | AK2: =Eingaben!A53 -> Betriebskosten ZEV (Administration und Abrechnung) | AL2: =Eingaben!A66 -> Betriebskosten LEG (Administration und Abrechnung) | AM2: =Eingaben!A119 -> Versicherung | AN2: =Eingaben!A120 -> Reparaturen | AO2: =Eingaben!A121 -> Reinigung Anlage | AP2: =Eingaben!A122 -> Grünbewuchs Pflege | AQ2: =Eingaben!A123 -> Transformator | AR2: =Eingaben!A124 -> Dach- / Raummiete | AS2: =Eingaben!A125 -> Wechselrichteraustausch | AT2: =Eingaben!A130 -> Ersatz Batteriespeicher | AU2: =Eingaben!A129 -> Unterhaltskosten Batteriespeicher
A3: Projektnummer: | M3: =IF(_Projektnummer<>"",_Projektnummer,"") | AF3: =VLOOKUP(AF2,Eingaben!$A$114:$H$125,3,FALSE) -> 830.688 | AG3: =VLOOKUP(AG2,Eingaben!$A$114:$H$125,3,FALSE) -> 0 | AH3: =VLOOKUP(AH2,Eingaben!$A$114:$H$125,3,FALSE) -> 69 | AI3: =VLOOKUP(AI2,Eingaben!$A$114:$H$125,3,FALSE) -> 99 | AJ3: =VLOOKUP(AJ2,Eingaben!$A$114:$H$125,3,FALSE) -> 120 | AK3: =VLOOKUP(AK2,Eingaben!$A$53:$H$133,3,FALSE) -> 0 | AL3: =VLOOKUP(AL2,Eingaben!$A$53:$H$133,3,FALSE) -> 0 | AM3: =VLOOKUP(AM2,Eingaben!$A$114:$H$125,3,FALSE) -> 49.1008 | AN3: =VLOOKUP(AN2,Eingaben!$A$114:$H$125,3,FALSE) -> 1215.344 | AO3: =VLOOKUP(AO2,Eingaben!$A$114:$H$125,3,FALSE) -> 1056.25 | AP3: =VLOOKUP(AP2,Eingaben!$A$114:$H$125,3,FALSE) -> 0 | AQ3: =VLOOKUP(AQ2,Eingaben!$A$114:$H$125,3,FALSE) -> 0 | AR3: =VLOOKUP(AR2,Eingaben!$A$114:$H$125,3,FALSE) -> 0 | AS3: =VLOOKUP(AS2,Eingaben!$A$114:$H$125,3,FALSE) -> 1175 | AT3: =VLOOKUP(AT2,Eingaben!$A$129:$F$130,3,FALSE) -> 0 | AU3: =VLOOKUP(AU2,Eingaben!$A$129:$F$130,3,FALSE) -> 0
A4: Projektbezeichnung: | M4: =_Projektbezeichnung&", "&_Standort -> , | AF4: =VLOOKUP(AF2,Eingaben!$A$114:$H$125,6,FALSE) -> 5 | AG4: =VLOOKUP(AG2,Eingaben!$A$114:$H$125,6,FALSE) -> 20 | AH4: =VLOOKUP(AH2,Eingaben!$A$114:$H$125,6,FALSE) -> 1 | AI4: =VLOOKUP(AI2,Eingaben!$A$114:$H$125,6,FALSE) -> 1 | AJ4: =VLOOKUP(AJ2,Eingaben!$A$114:$H$125,6,FALSE) -> 1 | AK4: 1 | AL4: 1 | AM4: =VLOOKUP(AM2,Eingaben!$A$114:$H$125,6,FALSE) -> 1 | AN4: =VLOOKUP(AN2,Eingaben!$A$114:$H$125,6,FALSE) -> 8 | AO4: =VLOOKUP(AO2,Eingaben!$A$114:$H$125,6,FALSE) -> 8 | AP4: =VLOOKUP(AP2,Eingaben!$A$114:$H$125,6,FALSE) -> 1 | AQ4: =VLOOKUP(AQ2,Eingaben!$A$114:$H$125,6,FALSE) -> 1 | AR4: =VLOOKUP(AR2,Eingaben!$A$114:$H$125,6,FALSE) -> 1 | AS4: =VLOOKUP(AS2,Eingaben!$A$114:$H$125,6,FALSE) -> 16 | AT4: =VLOOKUP(AT2,Eingaben!$A$129:$F$130,6,FALSE) -> 16 | AU4: =VLOOKUP(AU2,Eingaben!$A$129:$F$130,6,FALSE) -> 1 | BM4: =_xlfn.TRANSLATE(BM5,"de","en") -> Cost-effectiveness without battery storage | BS4: =_xlfn.TRANSLATE(BS5,"de","en") -> Cost-effectiveness with battery storage | BY4: =_xlfn.TRANSLATE(BY5,"de","en") -> Cost-effectiveness only battery storage
C5: =_xlfn.TRANSLATE(C6,"de","en") -> Year with lifetime | D5: =_xlfn.TRANSLATE(D6,"de","en") -> Year with battery life | E5: =_xlfn.TRANSLATE(E6,"de","en") -> Year of battery renewal | F5: =_xlfn.TRANSLATE(F6,"de","en") -> Year Payment Remuneration | G5: =_xlfn.TRANSLATE(G6,"de","en") -> Year of debt 1 PVA | H5: =_xlfn.TRANSLATE(H6,"de","en") -> Year of debt 2 PVA | I5: =_xlfn.TRANSLATE(I6,"de","en") -> Year of Debt Battery | J5: =_xlfn.TRANSLATE(J6,"de","en") -> Degradation PV system [% of new output] | ... BL5: =_xlfn.TRANSLATE(BL6,"de","en") -> Debt capital 1 battery Annuity [CHF] | BM5: Wirtschaftlichkeit ohne Batteriespeicher | BS5: Wirtschaftlichkeit mit Batteriespeicher | BY5: Wirtschaftlichkeit nur Batteriespeicher
B6: Jahr | C6: Jahr mit Lebensdauer | D6: Jahr mit Lebensdauer Batterie | E6: Jahr mit Erneuerung Batterie | F6: Jahr Auszahlung Vergütung | G6: Jahr Fremdkapital 1 PVA | H6: Jahr Fremdkapital 2 PVA | I6: Jahr Fremdkapital Batterie | J6: Degradation PV- Anlage [% der Neuleistung] | K6: Energieertrag [kWh] | L6: Degradation Batterie [% der Neukapazität] | M6: Batteriekapazität [kWh] | N6: Erhöhung EV mit Batterie [%] | O6: Eingelagerter Strom EV Batterie [kWh] | P6: Verluste Speicher [kWh] | Q6: Energie aus Speicher [kWh] | R6: Rückliefertarif mit Teuerung [CHF/kWh] | S6: Abnahme-vergütung [CHF] | T6: Tarif LEG mit Teuerung [CHF/kWh] | U6: Vergütung Stromverkauf LEG inkl. Abrechnunggebühr [CHF] | V6: eingesparter Bezug mit Teuerung [CHF/kWh] | W6: eingesparter Bezug / Stromverkauf ZEV [CHF] | X6: Leistungstarif mit Teuerung [CHF/kW/m] | Y6: Einsparung / PV Kosten ZEV Leistung [CHF] | Z6: Abrechnungsgebühren ZEV [CHF/kWh] | AA6: Grundkosten ZEV [CHF/Monat] | AB6: Abrechnungsgebühr ZEV mit Grundkosten [CHF] | AC6: eingesparter Bezug / Stromverkauf ZEV Batterie [CHF] | AD6: Einsparung / PV Kosten ZEV Leistung Batterie [CHF] | AE6: Kosten Energie für Ladung Batteriespeicher [CHF] | AF6: Unterhaltskosten nach Wartungstabelle [CHF] | AG6: Unterhaltskosten nach Wartungstabelle [CHF] | AH6: Unterhaltskosten nach Wartungstabelle [CHF] | AI6: Unterhaltskosten nach Wartungstabelle [CHF] | AJ6: Unterhaltskosten nach Wartungstabelle [CHF] | AK6: Unterhaltskosten nach Wartungstabelle [CHF] | AL6: Unterhaltskosten nach Wartungstabelle [CHF] | AM6: Unterhaltskosten nach Wartungstabelle [CHF] | AN6: Unterhaltskosten nach Wartungstabelle [CHF] | AO6: Unterhaltskosten nach Wartungstabelle [CHF] | AP6: Unterhaltskosten nach Wartungstabelle [CHF] | AQ6: Unterhaltskosten nach Wartungstabelle [CHF] | AR6: Unterhaltskosten nach Wartungstabelle [CHF] | AS6: Unterhaltskosten nach Wartungstabelle [CHF] | AT6: Unterhaltskosten nach Wartungstabelle [CHF] | AU6: Unterhaltskosten nach Wartungstabelle [CHF] | AV6: Unterhaltskosten nach Wartungstabelle Summe [CHF] | AW6: Faktor Teuerung Unterhaltskosten [CHF] | AX6: Betrieb und Unterhalts- Kosten PVA [CHF] | AY6: Betriebs- und Abrechungs-kosten ZEV [CHF] | AZ6: Betriebs- und Abrechungs-kosten LEG [CHF] | BA6: Betrieb und Unterhalts- Batteriespeicher [CHF] | BB6: MWSt- Umsatzsteuer [CHF] | BC6: MWSt- Abzug PVA Betrieb und Unterhalt [CHF] | BD6: MWSt- Abzug Batterie Betrieb und Unterhalt [CHF] | BE6: Auszahlung Vergütung [CHF] | BF6: Kapital EIV Für Verzinsung [CHF] | BG6: Verzinsung EIV [CHF] | BH6: Eigenkapitalkosten PVA (Verzinsung jährlich) Annuität [CHF] | BI6: Fremdkapital 1 PVA Annuität [CHF] | BJ6: Fremdkapital 2 PVA Annuität [CHF] | BK6: Eigenkapitalkosten Batterie (Verzinsung jährlich) Annuität [CHF] | BL6: Fremdkapital 1 Batterie Annuität [CHF] | BM6: Cash Flow netto [CHF] | BN6: Cash Flow netto ohne Fremdk. [CHF] | BO6: Kapitalentwicklung Cash Flow netto [CHF] | BP6: Barwert Cash Flow netto NPV [CHF] | BQ6: Kapitalentwicklung NPV [CHF] | BR6: Amortisationszeit ohne Speicher | BS6: Cash Flow netto [CHF] | BT6: Cash Flow netto ohne Fremdk. [CHF] | BU6: Kapitalentwicklung Cash Flow netto [CHF] | BV6: Barwert Cash Flow netto NPV [CHF] | BW6: Kapitalentwicklung NPV [CHF] | BX6: Amortisationszeit mit Speicher | BY6: Cash Flow netto [CHF] | BZ6: Cash Flow netto ohne Fremdk. [CHF] | CA6: Kapitalentwicklung Cash Flow netto [CHF] | CB6: Barwert Cash Flow netto NPV [CHF] | CC6: Kapitalentwicklung NPV [CHF] | CD6: Amortisationszeit nur Speicher
B7: 0 | M7: =_Speicherkapazität -> 0 | R7: =_Rückliefertarif -> 0.08 | T7: =IF(_LEG="JA",_Tarif_LEG,0) -> 0.096666667 | V7: =_ersetzterBezugstarifZEV -> 0.232 | X7: =_Leistungskosten_ZEV -> 1.5 | Z7: =IF(_ZEV="JA",_Tarif_Abrechnung_ZEV,0) -> 0 | AA7: =IF(_ZEV="JA",_Grundkosten_Abrechnung_ZEV,0) -> 8 | BM7: =-1*(_relevante_Investitionskosten-_direkteFörderung-_Steuereinsparung-_Fremdkapital1-_Fremdkapital2) -> -15344 | BN7: =-1*(_relevante_Investitionskosten-_direkteFörderung-_Steuereinsparung) -> -15344 | BP7: =BM7 -> -15344 | BS7: =-1*(_relevante_Investitionskosten+_relevante_Investitionskosten_Batterie-_direkteFörderung-_Steuereinsparung-_Förderung_Batterie-_Fremdkapital1-_Fremdkapital2-_Fremdkapital_Batterie) -> -15344 | BT7: =-1*(_relevante_Investitionskosten+_relevante_Investitionskosten_Batterie-_direkteFörderung-_Förderung_Batterie-_Steuereinsparung) -> -15344 | BV7: =BS7 -> -15344 | BY7: =-1*(_relevante_Investitionskosten_Batterie-_Förderung_Batterie-_Fremdkapital_Batterie) -> 0 | BZ7: =-1*(_relevante_Investitionskosten_Batterie-_Förderung_Batterie) -> 0 | CB7: =BY7 -> 0
